<mujoco model="a1">
  <compiler angle="radian" meshdir="./assets/"/>
  <asset>
    <mesh name="trunk" file="trunk.obj"/>
    <mesh name="hip" file="hip.obj"/>
    <mesh name="thigh_mirror" file="thigh_mirror.obj"/>
    <mesh name="calf" file="calf.obj"/>
    <mesh name="thigh" file="thigh.obj"/>
  </asset>
  <worldbody>
    <light name="spotlight" mode="targetbodycom" target="trunk" pos="0 -1 2"/>
    <body name="trunk" pos="0 0 0.43" >
    <freejoint/>
    <geom size="0.0005 0.0005 0.0005" type="box" contype="0" conaffinity="0" group="1" density="0"/>
    <geom type="mesh" contype="0" conaffinity="0" group="1" density="0" rgba="1 0.423529 0.0392157 1" mesh="trunk"/>
    <geom size="0.1335 0.097 0.057" type="box" rgba="1 0.423529 0.0392157 1"/>
    <geom size="0.0005 0.0005 0.0005" type="box" contype="0" conaffinity="0" group="1" density="0" rgba="0.8 0 0 1"/>
    <geom size="0.0005 0.0005 0.0005" type="box" rgba="0.8 0 0 1"/>
    <site name="imu" pos="0 0 0"/>
    <body name="FR_hip" pos="0.1805 -0.047 0">
      <inertial pos="-0.00266413 -0.0163358 2.49436e-05" quat="0.475134 0.521822 -0.477036 0.523818" mass="0.864993" diaginertia="0.00151807 0.00143717 0.000946744"/>
      <joint name="FR_hip_joint" pos="0 0 0" axis="1 0 0" range="-0.802851 0.802851" actuatorfrcrange="-33.5 33.5" damping="0.01" frictionloss="0.2"/>
      <geom quat="0 1 0 0" type="mesh" contype="0" conaffinity="0" group="1" density="0" rgba="1 0.423529 0.0392157 1" mesh="hip"/>
      <geom size="0.046 0.02" quat="0.707107 0.707107 0 0" type="cylinder" rgba="1 0.423529 0.0392157 1"/>
      <geom size="0.041 0.016" pos="0 -0.081 0" quat="0.707107 0.707107 0 0" type="cylinder"/>
      <body name="FR_thigh" pos="0 -0.0838 0">
        <inertial pos="-0.003237 0.022327 -0.027326" quat="0.999125 -0.00256393 -0.0409531 -0.00806091" mass="1.013" diaginertia="0.00555739 0.00513936 0.00133944"/>
        <joint name="FR_thigh_joint" pos="0 0 0" axis="0 1 0" range="-1.0472 4.18879" actuatorfrcrange="-33.5 33.5" damping="0.01" frictionloss="0.2"/>
        <geom type="mesh" contype="0" conaffinity="0" group="1" density="0" rgba="1 0.423529 0.0392157 1" mesh="thigh_mirror"/>
        <geom size="0.1 0.01225 0.017" pos="0 0 -0.1" quat="0.707107 0 0.707107 0" type="box" rgba="1 0.423529 0.0392157 1"/>
        <body name="FR_calf" pos="0 0 -0.2">
          <inertial pos="0.00472659 0 -0.131975" quat="0.706886 0.017653 0.017653 0.706886" mass="0.226" diaginertia="0.00340344 0.00339393 3.54834e-05"/>
          <joint name="FR_calf_joint" pos="0 0 0" axis="0 1 0" range="-2.69653 -0.916298" actuatorfrcrange="-33.5 33.5" damping="0.01" frictionloss="0.2"/>
          <geom type="mesh" contype="0" conaffinity="0" group="1" density="0" rgba="1 0.423529 0.0392157 1" mesh="calf"/>
          <geom size="0.1 0.008 0.008" pos="0 0 -0.1" quat="0.707107 0 0.707107 0" type="box" rgba="1 0.423529 0.0392157 1"/>
          <geom size="0.01" pos="0 0 -0.2" contype="0" conaffinity="0" group="1" density="0" rgba="1 0.423529 0.0392157 1"/>
          <geom size="0.02" pos="0 0 -0.2" rgba="1 0.423529 0.0392157 1"/>
        </body>
      </body>
    </body>
    <body name="FL_hip" pos="0.1805 0.047 0">
      <inertial pos="-0.00266413 0.0163358 2.49436e-05" quat="0.521822 0.475134 -0.523818 0.477036" mass="0.864993" diaginertia="0.00151807 0.00143717 0.000946744"/>
      <joint name="FL_hip_joint" pos="0 0 0" axis="1 0 0" range="-0.802851 0.802851" actuatorfrcrange="-33.5 33.5" damping="0.01" frictionloss="0.2"/>
      <geom type="mesh" contype="0" conaffinity="0" group="1" density="0" rgba="1 0.423529 0.0392157 1" mesh="hip"/>
      <geom size="0.046 0.02" quat="0.707107 0.707107 0 0" type="cylinder" rgba="1 0.423529 0.0392157 1"/>
      <geom size="0.041 0.016" pos="0 0.081 0" quat="0.707107 0.707107 0 0" type="cylinder"/>
      <body name="FL_thigh" pos="0 0.0838 0">
        <inertial pos="-0.003237 -0.022327 -0.027326" quat="0.999125 0.00256393 -0.0409531 0.00806091" mass="1.013" diaginertia="0.00555739 0.00513936 0.00133944"/>
        <joint name="FL_thigh_joint" pos="0 0 0" axis="0 1 0" range="-1.0472 4.18879" actuatorfrcrange="-33.5 33.5" damping="0.01" frictionloss="0.2"/>
        <geom type="mesh" contype="0" conaffinity="0" group="1" density="0" rgba="1 0.423529 0.0392157 1" mesh="thigh"/>
        <geom size="0.1 0.01225 0.017" pos="0 0 -0.1" quat="0.707107 0 0.707107 0" type="box" rgba="1 0.423529 0.0392157 1"/>
        <body name="FL_calf" pos="0 0 -0.2">
          <inertial pos="0.00472659 0 -0.131975" quat="0.706886 0.017653 0.017653 0.706886" mass="0.226" diaginertia="0.00340344 0.00339393 3.54834e-05"/>
          <joint name="FL_calf_joint" pos="0 0 0" axis="0 1 0" range="-2.69653 -0.916298" actuatorfrcrange="-33.5 33.5" damping="0.01" frictionloss="0.2"/>
          <geom type="mesh" contype="0" conaffinity="0" group="1" density="0" rgba="1 0.423529 0.0392157 1" mesh="calf"/>
          <geom size="0.1 0.008 0.008" pos="0 0 -0.1" quat="0.707107 0 0.707107 0" type="box" rgba="1 0.423529 0.0392157 1"/>
          <geom size="0.01" pos="0 0 -0.2" contype="0" conaffinity="0" group="1" density="0" rgba="1 0.423529 0.0392157 1"/>
          <geom size="0.02" pos="0 0 -0.2" rgba="1 0.423529 0.0392157 1"/>
        </body>
      </body>
    </body>
    <body name="RR_hip" pos="-0.1805 -0.047 0">
      <inertial pos="0.00266413 -0.0163358 2.49436e-05" quat="0.523818 0.477036 -0.521822 0.475134" mass="0.864993" diaginertia="0.00151807 0.00143717 0.000946744"/>
      <joint name="RR_hip_joint" pos="0 0 0" axis="1 0 0" range="-0.802851 0.802851" actuatorfrcrange="-33.5 33.5" damping="0.01" frictionloss="0.2"/>
      <geom quat="0 0 0 -1" type="mesh" contype="0" conaffinity="0" group="1" density="0" rgba="1 0.423529 0.0392157 1" mesh="hip"/>
      <geom size="0.046 0.02" quat="0.707107 0.707107 0 0" type="cylinder" rgba="1 0.423529 0.0392157 1"/>
      <geom size="0.041 0.016" pos="0 -0.081 0" quat="0.707107 0.707107 0 0" type="cylinder"/>
      <body name="RR_thigh" pos="0 -0.0838 0">
        <inertial pos="-0.003237 0.022327 -0.027326" quat="0.999125 -0.00256393 -0.0409531 -0.00806091" mass="1.013" diaginertia="0.00555739 0.00513936 0.00133944"/>
        <joint name="RR_thigh_joint" pos="0 0 0" axis="0 1 0" range="-1.0472 4.18879" actuatorfrcrange="-33.5 33.5" damping="0.01" frictionloss="0.2"/>
        <geom type="mesh" contype="0" conaffinity="0" group="1" density="0" rgba="1 0.423529 0.0392157 1" mesh="thigh_mirror"/>
        <geom size="0.1 0.01225 0.017" pos="0 0 -0.1" quat="0.707107 0 0.707107 0" type="box" rgba="1 0.423529 0.0392157 1"/>
        <body name="RR_calf" pos="0 0 -0.2">
          <inertial pos="0.00472659 0 -0.131975" quat="0.706886 0.017653 0.017653 0.706886" mass="0.226" diaginertia="0.00340344 0.00339393 3.54834e-05"/>
          <joint name="RR_calf_joint" pos="0 0 0" axis="0 1 0" range="-2.69653 -0.916298" actuatorfrcrange="-33.5 33.5" damping="0.01" frictionloss="0.2"/>
          <geom type="mesh" contype="0" conaffinity="0" group="1" density="0" rgba="1 0.423529 0.0392157 1" mesh="calf"/>
          <geom size="0.1 0.008 0.008" pos="0 0 -0.1" quat="0.707107 0 0.707107 0" type="box" rgba="1 0.423529 0.0392157 1"/>
          <geom size="0.01" pos="0 0 -0.2" contype="0" conaffinity="0" group="1" density="0" rgba="1 0.423529 0.0392157 1"/>
          <geom size="0.02" pos="0 0 -0.2" rgba="1 0.423529 0.0392157 1"/>
        </body>
      </body>
    </body>
    <body name="RL_hip" pos="-0.1805 0.047 0">
      <inertial pos="0.00266413 0.0163358 2.49436e-05" quat="0.477036 0.523818 -0.475134 0.521822" mass="0.864993" diaginertia="0.00151807 0.00143717 0.000946744"/>
      <joint name="RL_hip_joint" pos="0 0 0" axis="1 0 0" range="-0.802851 0.802851" actuatorfrcrange="-33.5 33.5" damping="0.01" frictionloss="0.2"/>
      <geom quat="0 0 1 0" type="mesh" contype="0" conaffinity="0" group="1" density="0" rgba="1 0.423529 0.0392157 1" mesh="hip"/>
      <geom size="0.046 0.02" quat="0.707107 0.707107 0 0" type="cylinder" rgba="1 0.423529 0.0392157 1"/>
      <geom size="0.041 0.016" pos="0 0.081 0" quat="0.707107 0.707107 0 0" type="cylinder"/>
      <body name="RL_thigh" pos="0 0.0838 0">
        <inertial pos="-0.003237 -0.022327 -0.027326" quat="0.999125 0.00256393 -0.0409531 0.00806091" mass="1.013" diaginertia="0.00555739 0.00513936 0.00133944"/>
        <joint name="RL_thigh_joint" pos="0 0 0" axis="0 1 0" range="-1.0472 4.18879" actuatorfrcrange="-33.5 33.5" damping="0.01" frictionloss="0.2"/>
        <geom type="mesh" contype="0" conaffinity="0" group="1" density="0" rgba="1 0.423529 0.0392157 1" mesh="thigh"/>
        <geom size="0.1 0.01225 0.017" pos="0 0 -0.1" quat="0.707107 0 0.707107 0" type="box" rgba="1 0.423529 0.0392157 1"/>
        <body name="RL_calf" pos="0 0 -0.2">
          <inertial pos="0.00472659 0 -0.131975" quat="0.706886 0.017653 0.017653 0.706886" mass="0.226" diaginertia="0.00340344 0.00339393 3.54834e-05"/>
          <joint name="RL_calf_joint" pos="0 0 0" axis="0 1 0" range="-2.69653 -0.916298" actuatorfrcrange="-33.5 33.5" damping="0.01" frictionloss="0.2"/>
          <geom type="mesh" contype="0" conaffinity="0" group="1" density="0" rgba="1 0.423529 0.0392157 1" mesh="calf"/>
          <geom size="0.1 0.008 0.008" pos="0 0 -0.1" quat="0.707107 0 0.707107 0" type="box" rgba="1 0.423529 0.0392157 1"/>
          <geom size="0.01" pos="0 0 -0.2" contype="0" conaffinity="0" group="1" density="0" rgba="1 0.423529 0.0392157 1"/>
          <geom size="0.02" pos="0 0 -0.2" rgba="1 0.423529 0.0392157 1"/>
        </body>
      </body>
    </body>
    </body>
  </worldbody>

  <actuator>
    <motor name="FR_hip" joint="FR_hip_joint" gear="1" ctrlrange="-33.5 33.5" ctrllimited='true' />
    <motor name="FR_thigh" joint="FR_thigh_joint" gear="1" ctrlrange="-33.5 33.5" ctrllimited='true' />
    <motor name="FR_calf" joint="FR_calf_joint" gear="1" ctrlrange="-33.5 33.5" ctrllimited='true' />
    <motor name="FL_hip" joint="FL_hip_joint" gear="1" ctrlrange="-33.5 33.5" ctrllimited='true' />
    <motor name="FL_thigh" joint="FL_thigh_joint" gear="1" ctrlrange="-33.5 33.5" ctrllimited='true' />
    <motor name="FL_calf" joint="FL_calf_joint" gear="1" ctrlrange="-33.5 33.5" ctrllimited='true' />
    <motor name="RR_hip" joint="RR_hip_joint" gear="1" ctrlrange="-33.5 33.5" ctrllimited='true' />
    <motor name="RR_thigh" joint="RR_thigh_joint" gear="1" ctrlrange="-33.5 33.5" ctrllimited='true' />
    <motor name="RR_calf" joint="RR_calf_joint" gear="1" ctrlrange="-33.5 33.5" ctrllimited='true' />
    <motor name="RL_hip" joint="RL_hip_joint" gear="1" ctrlrange="-33.5 33.5" ctrllimited='true' />
    <motor name="RL_thigh" joint="RL_thigh_joint" gear="1" ctrlrange="-33.5 33.5" ctrllimited='true' />
    <motor name="RL_calf" joint="RL_calf_joint" gear="1" ctrlrange="-33.5 33.5" ctrllimited='true' />
  </actuator>

  <sensor>
    <framequat name="imu_quat" objtype="site" objname="imu" />
    <gyro name="gyro" site="imu"/>
    <accelerometer name="acc" site="imu"/>
  </sensor>
</mujoco>
